Workbook

Sheet README
A1: THE UNLOX ACADEMY - DA/DS TRACK
A2: Excel Minor Project - Sales Operations Analytics
A3: Interview-Grade Data Analytics Assessment · 100 Marks
A5: THE SCENARIO
A6: You have just joined the analytics team at a fast-growing multi-category retailer operating across 6 Indian cities.
A7: The head of sales has handed you 5 raw data files - Orders, Customers, Products, Sales Reps, and Targets - and asked
A8: you to answer a set of business questions before the leadership review tomorrow morning.
A10: The data is REAL-WORLD messy: duplicates, missing references, inconsistent case, invalid records, discontinued SKUs.
A11: Part of the assessment is spotting and handling these issues correctly. A wrong-looking answer isn't always wrong -
A12: sometimes the data itself is telling a story.
A14: RULES OF THE ASSESSMENT
A15: 1. Write your answer in the YELLOW cells on each question sheet. Empty answer cell = 0 marks.
... A22: MARKS DISTRIBUTION
A23: Section | B23: Topic | C23: Questions | D23: Marks
A24: Q1 | B24: Lookup Functions (VLOOKUP, INDEX-MATCH, chained lookups) | C24: 8 | D24: 25
A25: Q2 | B25: Data Cleaning & Quality Diagnostics | C25: 6 | D25: 20
A26: Q3 | B26: Conditional Aggregation (SUMIFS, COUNTIFS, IF logic) | C26: 6 | D26: 25
A27: Q4 | B27: Pivot Tables (2D pivots, % of total, calculated fields) | C27: 5 | D27: 20
A28: Q5 | B28: Advanced (Ranking, Running Totals, Multi-condition) | C28: 5 | D28: 10
B29: TOTAL | C29: 30 | D29: 100
A32: PERFORMANCE TIERS
A33: Marks | B33: Tier | C33: Interview Verdict
A34: 85 - 100 | B34: Excellent | C34: Round 1 clear - Excel not a concern
A35: 70 - 84 | B35: Good | C35: Round 1 clear with minor gaps
A36: 55 - 69 | B36: Borderline | C36: Round 1 uncertain - needs revision
A37: 40 - 54 | B37: Weak | C37: Round 1 likely reject - 2 weeks of practice needed
A38: < 40 | B38: Insufficient | C38: Round 1 reject - foundational gaps
A41: DATA SHEETS OVERVIEW
A42: Sheet | B42: Rows | C42: Key Columns | D42: Joins to
A43: Orders | B43: ~2000 | C43: order_id, order_date, customer_id, product_id, sales_rep_id, quantity, unit_price, discount_pct, final_amount, payment_status, ship_city | D43: All others
A44: Customers | B44: 300 | C44: customer_id (PK), customer_name, age, city, segment, signup_date | D44: Orders via customer_id
A45: Products | B45: 60 | C45: product_id (PK), product_name, category, unit_cost, unit_price, is_active | D45: Orders via product_id
A46: Sales_Reps | B46: 30 | C46: rep_id (PK), rep_name, region, hire_date, team_lead_id | D46: Orders via sales_rep_id, self-join via team_lead_id
A47: Targets | B47: 30 × 12 | C47: rep_id (PK), Jan-24 through Dec-24 monthly target values | D47: Sales_Reps via rep_id

Sheet Orders
A1: order_id | B1: order_date | C1: customer_id | D1: product_id | E1: sales_rep_id | F1: quantity | G1: unit_price | H1: discount_pct | I1: final_amount | J1: payment_status | K1: ship_city | L1: category | M1: sales_region | N1: order_month | O1: order_quarters | P1: unit_cost | Q1: profit_margin
A2: ORD-00001 | B2: 45549 | C2: CUST-0243 | D2: PROD-014 | E2: R007 | F2: 8 | G2: 3620 | H2: 15.4 | I2: 24500.16 | J2: Completed | K2: Pune | L2: =VLOOKUP(D2,Products!$A:$F,3,FALSE) -> Apparel | M2: =VLOOKUP(E2,Sales_Reps!$A:$E,3,FALSE) -> North | N2: =TEXT(B2, "mmm-yy") -> Sep-24 | O2: ="Q" & INT((MONTH(B2)-1)/3)+1 & " " & YEAR(B2) -> Q3 2024 | P2: =VLOOKUP(D2,Products!$A:$F,4,FALSE) -> 2509 | Q2: =(G2 - P2) / G2 -> 0.30690608
A3: ORD-00002 | B3: 45340 | C3: CUST-0202 | D3: PROD-020 | E3: R005 | F3: 2 | G3: 820 | H3: 10.8 | I3: 1462.88 | J3: Pending | K3: Chennai | L3: =VLOOKUP(D3,Products!$A:$F,3,FALSE) -> Apparel | M3: =VLOOKUP(E3,Sales_Reps!$A:$E,3,FALSE) -> North | N3: =TEXT(B3, "mmm-yy") -> Feb-24 | O3: ="Q" & INT((MONTH(B3)-1)/3)+1 & " " & YEAR(B3) -> Q1 2024 | P3: =VLOOKUP(D3,Products!$A:$F,4,FALSE) -> 391 | Q3: =(G3 - P3) / G3 -> 0.52317073
A4: ORD-00003 | B4: 45371 | C4: CUST-0098 | D4: PROD-053 | E4: R014 | F4: 8 | G4: 470 | H4: 3.3 | I4: 3635.92 | J4: Pending | K4: Delhi | L4: =VLOOKUP(D4,Products!$A:$F,3,FALSE) -> Sports | M4: =VLOOKUP(E4,Sales_Reps!$A:$E,3,FALSE) -> South | N4: =TEXT(B4, "mmm-yy") -> Mar-24 | O4: ="Q" & INT((MONTH(B4)-1)/3)+1 & " " & YEAR(B4) -> Q1 2024 | P4: =VLOOKUP(D4,Products!$A:$F,4,FALSE) -> 302 | Q4: =(G4 - P4) / G4 -> 0.35744681
A5: ORD-00004 | B5: 45413 | C5: CUST-0071 | D5: PROD-028 | E5: R006 | F5: 1 | G5: 3660 | H5: 15.7 | I5: 3085.38 | J5: Completed | K5: Delhi | L5: =VLOOKUP(D5,Products!$A:$F,3,FALSE) -> Grocery | M5: =VLOOKUP(E5,Sales_Reps!$A:$E,3,FALSE) -> North | N5: =TEXT(B5, "mmm-yy") -> May-24 | O5: ="Q" & INT((MONTH(B5)-1)/3)+1 & " " & YEAR(B5) -> Q2 2024 | P5: =VLOOKUP(D5,Products!$A:$F,4,FALSE) -> 2214 | Q5: =(G5 - P5) / G5 -> 0.39508197
A6: ORD-00005 | B6: 45611 | C6: CUST-0180 | D6: PROD-012 | E6: R008 | F6: 1 | G6: 3160 | H6: 26 | I6: 2338.4 | J6: Completed | K6: Chennai | L6: =VLOOKUP(D6,Products!$A:$F,3,FALSE) -> Apparel | M6: =VLOOKUP(E6,Sales_Reps!$A:$E,3,FALSE) -> North | N6: =TEXT(B6, "mmm-yy") -> Nov-24 | O6: ="Q" & INT((MONTH(B6)-1)/3)+1 & " " & YEAR(B6) -> Q4 2024 | P6: =VLOOKUP(D6,Products!$A:$F,4,FALSE) -> 1886 | Q6: =(G6 - P6) / G6 -> 0.40316456
A7: ORD-00006 | B7: 45406 | C7: CUST-0275 | D7: PROD-032 | E7: R025 | F7: 4 | G7: 370 | H7: 29 | I7: 1050.8 | J7: Completed | K7: Mumbai | L7: =VLOOKUP(D7,Products!$A:$F,3,FALSE) -> Home | M7: =VLOOKUP(E7,Sales_Reps!$A:$E,3,FALSE) -> West | N7: =TEXT(B7, "mmm-yy") -> Apr-24 | O7: ="Q" & INT((MONTH(B7)-1)/3)+1 & " " & YEAR(B7) -> Q2 2024 | P7: =VLOOKUP(D7,Products!$A:$F,4,FALSE) -> 288 | Q7: =(G7 - P7) / G7 -> 0.22162162
A8: ORD-00007 | B8: 45455 | C8: CUST-0293 | D8: PROD-057 | E8: R024 | F8: 3 | G8: 960 | H8: 5.8 | I8: 2712.96 | J8: Completed | K8: Bengaluru | L8: =VLOOKUP(D8,Products!$A:$F,3,FALSE) -> Sports | M8: =VLOOKUP(E8,Sales_Reps!$A:$E,3,FALSE) -> West | N8: =TEXT(B8, "mmm-yy") -> Jun-24 | O8: ="Q" & INT((MONTH(B8)-1)/3)+1 & " " & YEAR(B8) -> Q2 2024 | P8: =VLOOKUP(D8,Products!$A:$F,4,FALSE) -> 705 | Q8: =(G8 - P8) / G8 -> 0.265625
A9: ORD-00008 | B9: 45617 | C9: CUST-0281 | D9: PROD-007 | E9: R019 | F9: 8 | G9: 1430 | H9: 2.4 | I9: 11165.44 | J9: Completed | K9: Bengaluru | L9: =VLOOKUP(D9,Products!$A:$F,3,FALSE) -> Electronics | M9: =VLOOKUP(E9,Sales_Reps!$A:$E,3,FALSE) -> East | N9: =TEXT(B9, "mmm-yy") -> Nov-24 | O9: ="Q" & INT((MONTH(B9)-1)/3)+1 & " " & YEAR(B9) -> Q4 2024 | P9: =VLOOKUP(D9,Products!$A:$F,4,FALSE) -> 861 | Q9: =(G9 - P9) / G9 -> 0.3979021
A10: ORD-00009 | B10: 45549 | C10: CUST-0260 | D10: PROD-038 | E10: R008 | F10: 3 | G10: 5490 | H10: 14.2 | I10: 14131.26 | J10: Completed | K10: Bengaluru | L10: =VLOOKUP(D10,Products!$A:$F,3,FALSE) -> Home | M10: =VLOOKUP(E10,Sales_Reps!$A:$E,3,FALSE) -> North | N10: =TEXT(B10, "mmm-yy") -> Sep-24 | O10: ="Q" & INT((MONTH(B10)-1)/3)+1 & " " & YEAR(B10) -> Q3 2024 | P10: =VLOOKUP(D10,Products!$A:$F,4,FALSE) -> 2549 | Q10: =(G10 - P10) / G10 -> 0.53570128
A11: ORD-00010 | B11: 45396 | C11: CUST-0147 | D11: PROD-030 | E11: R028 | F11: 3 | G11: 970 | H11: 1.2 | I11: 2875.08 | J11: Completed | K11: Pune | L11: =VLOOKUP(D11,Products!$A:$F,3,FALSE) -> Grocery | M11: =VLOOKUP(E11,Sales_Reps!$A:$E,3,FALSE) -> West | N11: =TEXT(B11, "mmm-yy") -> Apr-24 | O11: ="Q" & INT((MONTH(B11)-1)/3)+1 & " " & YEAR(B11) -> Q2 2024 | P11: =VLOOKUP(D11,Products!$A:$F,4,FALSE) -> 434 | Q11: =(G11 - P11) / G11 -> 0.55257732
A12: ORD-00011 | B12: 45560 | C12: CUST-0204 | D12: PROD-024 | E12: R010 | F12: 7 | G12: 2270 | H12: 7.1 | I12: 14761.81 | J12: Pending | K12: Hyderabad | L12: =VLOOKUP(D12,Products!$A:$F,3,FALSE) -> Grocery | M12: =VLOOKUP(E12,Sales_Reps!$A:$E,3,FALSE) -> South | N12: =TEXT(B12, "mmm-yy") -> Sep-24 | O12: ="Q" & INT((MONTH(B12)-1)/3)+1 & " " & YEAR(B12) -> Q3 2024 | P12: =VLOOKUP(D12,Products!$A:$F,4,FALSE) -> 1203 | Q12: =(G12 - P12) / G12 -> 0.47004405
A13: ORD-00012 | B13: 45332 | C13: CUST-0147 | D13: PROD-010 | E13: R024 | F13: 9 | G13: 2640 | H13: 21.7 | I13: 18604.08 | J13: Completed | K13: Pune | L13: =VLOOKUP(D13,Products!$A:$F,3,FALSE) -> Electronics | M13: =VLOOKUP(E13,Sales_Reps!$A:$E,3,FALSE) -> West | N13: =TEXT(B13, "mmm-yy") -> Feb-24 | O13: ="Q" & INT((MONTH(B13)-1)/3)+1 & " " & YEAR(B13) -> Q1 2024 | P13: =VLOOKUP(D13,Products!$A:$F,4,FALSE) -> 1149 | Q13: =(G13 - P13) / G13 -> 0.56477273
... A2001: ORD-02000 | B2001: 45325 | C2001: CUST-0238 | D2001: PROD-034 | E2001: R023 | F2001: 6 | G2001: 5080 | H2001: 28.1 | I2001: 21915.12 | J2001: Completed | K2001: Delhi | L2001: =VLOOKUP(D2001,Products!$A:$F,3,FALSE) -> Home | M2001: =VLOOKUP(E2001,Sales_Reps!$A:$E,3,FALSE) -> East | N2001: =TEXT(B2001, "mmm-yy") -> Feb-24 | O2001: ="Q" & INT((MONTH(B2001)-1)/3)+1 & " " & YEAR(B2001) -> Q1 2024 | P2001: =VLOOKUP(D2001,Products!$A:$F,4,FALSE) -> 2459 | Q2001: =(G2001 - P2001) / G2001 -> 0.51594488

Sheet Customers
A1: customer_id | B1: customer_name | C1: age | D1: city | E1: segment | F1: signup_date
A2: CUST-0001 | B2: Amit Agarwal | C2: 36 | D2: Pune | E2: Retail | F2: 44819
A3: CUST-0002 | B3: Vihaan Malhotra | C3: 42 | D3: Pune | E3: Corporate | F3: 44984
A4: CUST-0003 | B4: Navya Malhotra | C4: 33 | D4: Mumbai | E4: Retail | F4: 44059
A5: CUST-0004 | B5: Aaradhya Mehta | C5: 53 | D5: delhi | E5: Retail | F5: 44054
A6: CUST-0005 | B6: Myra Malhotra | C6: 52 | D6: Chennai | E6: Corporate | F6: 45037
A7: CUST-0006 | B7: Shaurya Iyer | C7: 44 | D7: Pune | E7: SMB | F7: 44302
A8: CUST-0007 | B8: Dhruv Joshi | C8: 47 | D8: Bengaluru | E8: Retail | F8: 44498
A9: CUST-0008 | B9: Kavita Malhotra | C9: 39 | D9: Pune | E9: SMB | F9: 45162
A10: CUST-0009 | B10: Neha Malhotra | C10: 61 | D10: Mumbai | E10: Retail | F10: 44343
A11: CUST-0010 | B11: Aaradhya Gupta | C11: 61 | D11: Mumbai | E11: SMB | F11: 44975
A12: CUST-0011 | B12: Diya Menon | C12: 41 | D12: Chennai | E12: Corporate | F12: 44821
A13: CUST-0012 | B13: Prisha Desai | C13: 43 | D13: Pune | E13: Retail | F13: 44718
... A301: CUST-0300 | B301: Rohit Nair | C301: 38 | D301: Mumbai | E301: Retail | F301: 43932

Sheet Products
A1: product_id | B1: product_name | C1: category | D1: unit_cost | E1: unit_price | F1: is_active
A2: PROD-001 | B2: Smartphone Pro | C2: Electronics | D2: 2405 | E2: 5330 | F2: TRUE
A3: PROD-002 | B3: Wireless Earbuds | C3: Electronics | D3: 1052 | E3: 2600 | F3: TRUE
A4: PROD-003 | B4: Smart Watch | C4: Electronics | D4: 1665 | E4: 3570 | F4: TRUE
A5: PROD-004 | B5: Laptop Bag | C5: Electronics | D5: 1559 | E5: 3870 | F5: TRUE
A6: PROD-005 | B6: Power Bank | C6: Electronics | D6: 128 | E6: 300 | F6: TRUE
A7: PROD-006 | B7: Bluetooth Speaker | C7: Electronics | D7: 2865 | E7: 3970 | F7: TRUE
A8: PROD-007 | B8: USB-C Cable | C8: Electronics | D8: 861 | E8: 1430 | F8: TRUE
A9: PROD-008 | B9: Wireless Mouse | C9: Electronics | D9: 1259 | E9: 2660 | F9: FALSE
A10: PROD-009 | B10: Mechanical Keyboard | C10: Electronics | D10: 517 | E10: 1220 | F10: TRUE
A11: PROD-010 | B11: Tablet Stand | C11: Electronics | D11: 1149 | E11: 2640 | F11: TRUE
A12: PROD-011 | B12: Cotton T-Shirt | C12: Apparel | D12: 1748 | E12: 3450 | F12: TRUE
A13: PROD-012 | B13: Denim Jeans | C13: Apparel | D13: 1886 | E13: 3160 | F13: TRUE
... A61: PROD-060 | B61: Gym Gloves | C61: Sports | D61: 147 | E61: 190 | F61: TRUE

Sheet Sales_Reps
A1: rep_id | B1: rep_name | C1: region | D1: hire_date | E1: team_lead_id
A2: R001 | B2: Rajesh Malhotra | C2: North | D2: 44207
A3: R002 | B3: Sunita Malhotra | C3: North | D3: 44028
A4: R003 | B4: Amit Singh | C4: North | D4: 43651
A5: R004 | B5: Priya Singh | C5: North | D5: 44907
A6: R005 | B6: Vikram Patel | C6: North | D6: 43588 | E6: R001
A7: R006 | B7: Neha Desai | C7: North | D7: 44131 | E7: R001
A8: R007 | B8: Suresh Menon | C8: North | D8: 43493 | E8: R001
A9: R008 | B9: Kavita Patel | C9: North | D9: 44693 | E9: R001
A10: R009 | B10: Manoj Patel | C10: South | D10: 44804 | E10: R002
A11: R010 | B11: Divya Rao | C11: South | D11: 43904 | E11: R002
A12: R011 | B12: Anil Verma | C12: South | D12: 44622 | E12: R002
A13: R012 | B13: Pooja Nair | C13: South | D13: 44890 | E13: R002
A14: R013 | B14: Sanjay Kapoor | C14: South | D14: 45215 | E14: R002
A15: R014 | B15: Ritu Menon | C15: South | D15: 44469 | E15: R002
A16: R015 | B16: Deepak Shah | C16: South | D16: 45231 | E16: R002
A17: R016 | B17: Anjali Chopra | C17: South | D17: 43614 | E17: R002
... A31: R030 | B31: Kiran Bhatt | C31: West | D31: 44506 | E31: R004

Sheet Targets
A1: rep_id | B1: Jan-24 | C1: Feb-24 | D1: Mar-24 | E1: Apr-24 | F1: May-24 | G1: Jun-24 | H1: Jul-24 | I1: Aug-24 | J1: Sep-24 | K1: Oct-24 | L1: Nov-24 | M1: Dec-24
A2: R001 | B2: 231324 | C2: 171682 | D2: 234376 | E2: 326967 | F2: 350588 | G2: 385324 | H2: 307980 | I2: 327947 | J2: 181016 | K2: 374039 | L2: 212805 | M2: 405999
A3: R002 | B3: 438126 | C3: 346266 | D3: 329993 | E3: 370744 | F3: 294660 | G3: 341556 | H3: 151934 | I3: 223794 | J3: 438641 | K3: 344308 | L3: 296172 | M3: 304288
A4: R003 | B4: 358703 | C4: 320519 | D4: 327321 | E4: 298753 | F4: 254636 | G4: 351929 | H4: 264723 | I4: 216459 | J4: 391945 | K4: 362426 | L4: 289199 | M4: 301863
A5: R004 | B5: 389594 | C5: 376422 | D5: 324156 | E5: 420255 | F5: 409107 | G5: 269954 | H5: 179097 | I5: 370568 | J5: 387395 | K5: 243454 | L5: 232530 | M5: 201999
A6: R005 | B6: 436862 | C6: 391158 | D6: 340224 | E6: 170548 | F6: 229390 | G6: 349525 | H6: 154683 | I6: 320848 | J6: 354452 | K6: 377180 | L6: 342347 | M6: 183362
A7: R006 | B7: 348734 | C7: 358191 | D7: 250385 | E7: 219657 | F7: 249365 | G7: 435704 | H7: 260892 | I7: 250741 | J7: 358402 | K7: 379858 | L7: 213280 | M7: 224634
A8: R007 | B8: 280057 | C8: 330342 | D8: 336856 | E8: 227425 | F8: 233647 | G8: 307088 | H8: 370724 | I8: 440008 | J8: 406347 | K8: 217357 | L8: 299289 | M8: 214568
A9: R008 | B9: 252886 | C9: 206057 | D9: 318209 | E9: 411230 | F9: 448660 | G9: 171135 | H9: 305339 | I9: 432264 | J9: 294273 | K9: 371409 | L9: 284207 | M9: 437068
A10: R009 | B10: 268752 | C10: 393256 | D10: 310649 | E10: 246237 | F10: 271287 | G10: 314545 | H10: 406506 | I10: 334930 | J10: 348625 | K10: 408928 | L10: 243749 | M10: 418409
A11: R010 | B11: 384734 | C11: 156698 | D11: 283679 | E11: 276085 | F11: 409270 | G11: 285230 | H11: 304233 | I11: 178221 | J11: 284216 | K11: 287373 | L11: 229082 | M11: 298969
A12: R011 | B12: 186029 | C12: 151419 | D12: 253251 | E12: 379757 | F12: 204209 | G12: 179396 | H12: 378008 | I12: 182649 | J12: 267772 | K12: 350352 | L12: 358042 | M12: 359960
A13: R012 | B13: 352158 | C13: 251181 | D13: 321255 | E13: 300863 | F13: 241731 | G13: 393275 | H13: 313561 | I13: 283604 | J13: 429065 | K13: 194420 | L13: 254168 | M13: 389283
... A31: R030 | B31: 151584 | C31: 221679 | D31: 385157 | E31: 290386 | F31: 236041 | G31: 407985 | H31: 184446 | I31: 342894 | J31: 180344 | K31: 292917 | L31: 314858 | M31: 364057

Sheet Q1_Lookups
A1: Q1 - LOOKUP FUNCTIONS (25 marks total)
A2: VLOOKUP · INDEX-MATCH · Two-way lookup · Chain lookup · Approximate lookup · Self-join
A4: Q# | B4: Question | C4: Marks | D4: Your Answer | E4: Format
A5: Q1.1 | B5: For order ORD-00234, what is the customer_id? | C5: 3 | D5: =VLOOKUP("ORD-00234",Orders!$A:$K,3,FALSE) -> CUST-0173 | E5: CUST-####
A6: Q1.2 | B6: For order ORD-00456, what is the product_name? (You will need to look up the product_id first, then find its name in Products.) | C6: 3 | D6: =VLOOKUP(VLOOKUP("ORD-00456",Orders!$A:$K,4,FALSE),Products!$A:$F,2,FALSE) -> Dumbbells 5kg | E6: Text
A7: Q1.3 | B7: For order ORD-00987, what is the rep_name of the sales rep? Note: the rep_name is in a column that appears to the LEFT of what you might look up first. | C7: 3 | D7: =VLOOKUP(VLOOKUP("ORD-00987",Orders!$A:$K,5,FALSE),Sales_Reps!$A:$E,2,FALSE) -> Nisha Menon | E7: Text
A8: Q1.4 | B8: From the Targets sheet, what is the target value for rep R012 in the month Mar-24? | C8: 4 | D8: =INDEX(Targets!B2:M100, MATCH("R012", Targets!A2:A100, 0), MATCH("Mar-24", Targets!B1:M1, 0)) -> 321255 | E8: Whole number
A9: Q1.5 | B9: For order ORD-01500, what is the CATEGORY of the product ordered? (Chain: order → product_id → category) | C9: 4 | D9: =VLOOKUP(VLOOKUP("ORD-01500",Orders!$A:$K,4,FALSE),Products!$A:$F,3,FALSE) -> Electronics | E9: Text
A10: Q1.6 | B10: For order ORD-00789, which DISCOUNT SLAB does it fall in? Use the slab table below (rows 20-24). Slab breakpoints are the LOWER bound of each range. | C10: 3 | D10: =VLOOKUP(VLOOKUP("ORD-00789",Orders!$A$2:$H$2001,8,FALSE),$B$17:$C$20,2,TRUE) -> Bronze | E10: Text
A11: Q1.7 | B11: For order ORD-01234, in one cell produce the string: "<rep_name> (<sales_region>)" - e.g. "Amit Singh (South)". | C11: 3 | D11: =VLOOKUP(VLOOKUP("ORD-01234",Orders!$A:$K,5,FALSE),Sales_Reps!$A:$E,2,FALSE)&" ("&VLOOKUP(VLOOKUP("ORD-01234",Orders!$A:$K,5,FALSE),Sales_Reps!$A:$E,3,FALSE)&")" -> Sanjay Kapoor (South) | E11: Text
A12: Q1.8 | B12: What is the rep_name of the TEAM LEAD for rep R017? (The Sales_Reps sheet has team_lead_id - you need to self-join to find that person's name.) | C12: 2 | D12: =VLOOKUP(VLOOKUP("R017",Sales_Reps!$A:$E,5,FALSE),Sales_Reps!$A:$E,2,FALSE) -> Amit Singh | E12: Text
B15: DISCOUNT SLAB REFERENCE TABLE (use for Q1.6)
B17: Discount % (Lower) | C17: Slab
B18: 0 | C18: Bronze
B19: 5 | C19: Silver
B20: 15 | C20: Gold
B21: 25 | C21: Platinum

Sheet Q2_Cleaning
A1: Q2 - DATA CLEANING & QUALITY DIAGNOSTICS (20 marks total)
A2: Duplicates · Whitespace · Case Inconsistency · Referential Integrity · Discontinued SKUs · Anomaly Patterns
A4: Q# | B4: Question | C4: Marks | D4: Your Answer | E4: Format
A5: Q2.1 | B5: How many DUPLICATE rows exist in the Orders sheet (i.e., how many order_id values appear more than once)? Count each duplicate as ONE (not the extras). | C5: 3 | D5: {=SUMPRODUCT(--(COUNTIF(Orders!A2:A2001, _xlfn.UNIQUE(Orders!A2:A2001))>1))} -> 20 | E5: Whole number
A6: Q2.2 | B6: How many customers in the Customers sheet have LEADING or TRAILING whitespace in their customer_name? | C6: 3 | D6: {=SUMPRODUCT(--(LEN(Customers!B2:B301)<>LEN(TRIM(Customers!B2:B301))))} -> 15 | E6: Whole number
A7: Q2.3 | B7: The Customers sheet has some cities in inconsistent case (e.g., "mumbai", "MUMBAI", "Mumbai"). How many DISTINCT cities exist AFTER standardizing case? | C7: 3 | D7: {=COUNTA(_xlfn.UNIQUE(PROPER(TRIM(Customers!D2:D301))))} -> 6 | E7: Whole number
A8: Q2.4 | B8: How many orders reference a customer_id that DOES NOT EXIST in the Customers sheet? (Broken foreign key) | C8: 4 | D8: {=SUMPRODUCT(--ISNA(MATCH(Orders!C2:C2001, Customers!A2:A301, 0)))} -> 30 | E8: Whole number
A9: Q2.5 | B9: How many orders reference a product that is currently DISCONTINUED (is_active = FALSE in the Products sheet)? | C9: 3 | D9: {=SUMPRODUCT(--(_xlfn.XLOOKUP(Orders!D2:D2001, Products!A2:A61, Products!F2:F61)=FALSE))} -> 174 | E9: Whole number
A10: Q2.6 | B10: Find the "suspicious pattern": how many orders have payment_status = "Cancelled" AND a discount_pct > 20%? (This pattern often indicates promo abuse - a real-world diagnostic query.) | C10: 4 | D10: =COUNTIFS(Orders!J2:J2001, "Cancelled", Orders!H2:H2001, ">20") -> 58 | E10: Whole number

Sheet Q3_Aggregation
A1: Q3 - CONDITIONAL AGGREGATION (25 marks total)
A2: SUMIFS · COUNTIFS · AVERAGEIFS · Nested IF logic · Multi-sheet aggregation · Top-N logic
A4: Q# | B4: Question | C4: Marks | D4: Your Answer | E4: Format
A5: Q3.1 | B5: What is the TOTAL REVENUE (sum of final_amount) for orders in Q3 2024 (Jul-Sep) where ship_city is Mumbai? | C5: 4 | D5: =SUMIFS(Orders!$I:$I,Orders!$B:$B,">="&DATE(2024,7,1),Orders!$B:$B,"<"&DATE(2024,10,1),Orders!$K:$K,"Mumbai") -> 1217239 | E5: Currency
A6: Q3.2 | B6: How many orders have discount_pct > 15% AND payment_status = "Completed"? | C6: 3 | D6: =COUNTIFS(Orders!$H:$H,">15",Orders!$J:$J,"Completed") -> 723 | E6: Whole number
A7: Q3.3 | B7: What is the AVERAGE final_amount for orders where the product CATEGORY is "Electronics" AND the customer SEGMENT is "Corporate"? Note: Both fields come from OTHER sheets - you'll need helper columns. | C7: 5 | D7: {=AVERAGE(_xlfn._xlws.FILTER(Orders!I2:I2001,(_xlfn.XLOOKUP(Orders!D2:D2001,Products!A2:A61,Products!C2:C61,"")="Electronics")*(_xlfn.XLOOKUP(Orders!C2:C2001,Customers!A2:A301,Customers!E2:E301,"")="Corporate")))} -> 13981.402 | E7: Currency
A8: Q3.4 | B8: What is the COMBINED REVENUE of the TOP 3 reps by total revenue? (Sum of the 3 highest rep totals.) | C8: 4 | D8: {=SUMPRODUCT(LARGE(SUMIF(Orders!E2:E2001, Sales_Reps!A2:A31, Orders!I2:I2001), {1,2,3}))} -> 3342678.5 | E8: Currency
A9: Q3.5 | B9: For rep R015 in Nov-24: compute the actual revenue and compare to the target (from Targets sheet). Report the PERFORMANCE TIER using: <80% → "Below", 80-120% → "On Track", >120% → "Exceeds". Return only the tier text. | C9: 5 | D9: {=_xlfn.IFS(SUMIFS(Orders!I2:I2001, Orders!E2:E2001, "R015", Orders!B2:B2001, ">=2024-11-01", Orders!B2:B2001, "<=2024-11-30") / VLOOKUP("R015", Targets!A:M, 12, FALSE) < 0.8, "Below", SUMIFS(Orders!I2:I2001, Orders!E2:E2001, "R015", Orders!B2:B2001, ">=2024-11-01", Orders!B2:B2001, "<=2024-11-30") / VLOOKUP("R015", Targets!A:M, 12, FALSE) <= 1.2, "On Track", TRUE, "Exceeds")} -> Below | E9: Text
A10: Q3.6 | B10: What is the TOTAL revenue from Corporate segment customers aged between 30 and 40 (both inclusive)? | C10: 4 | D10: {=SUM(_xlfn._xlws.FILTER(Orders!I2:I2001,(_xlfn.XLOOKUP(Orders!C2:C2001,Customers!A2:A301,Customers!E2:E301,"")="Corporate")*(_xlfn.XLOOKUP(Orders!C2:C2001,Customers!A2:A301,Customers!C2:C301,"")>=30)*(_xlfn.XLOOKUP(Orders!C2:C2001,Customers!A2:A301,Customers!C2:C301,"")<=40)))} -> 982568.4 | E10: Currency

Sheet Q4_Pivot
A1: Q4 - PIVOT TABLES (20 marks total)
A2: 2D Pivots · Filters · % of Row Total · Date Grouping · Calculated Fields · Cross-Sheet Data
A4: Q# | B4: Question | C4: Marks | D4: Your Answer | E4: Format
A5: Q4.1 | B5: Build a pivot with sales_region as rows and product category as columns, values = SUM of final_amount. What value appears at the intersection of "South" and "Electronics"? | C5: 4 | D5: =SUMIFS(Orders!$I:$I,Orders!$M:$M,"South",Orders!$L:$L,"Electronics") -> 1314107.4 | E5: Currency
A6: Q4.2 | B6: Build a pivot: rows = order month (Jan-24 through Dec-24), columns = sales_rep_id, values = SUM of final_amount. What is the HIGHEST single value in the entire pivot? (One number.) | C6: 4 | D6: =MAX(F26:AJ37) -> 216421.52 | E6: Currency
A7: Q4.3 | B7: For the North sales_region only: what PERCENTAGE of total revenue comes from the Apparel category? Configure the pivot with Show Values As → % of Row Total. | C7: 4 | D7: =SUMIFS(Orders!$I:$I,Orders!$M:$M,"North",Orders!$L:$L,"Apparel")/SUMIFS(Orders!$I:$I,Orders!$M:$M,"North") -> 0.1402315 | E7: Percentage
A8: Q4.4 | B8: Group order dates by QUARTER in a pivot. What is the total revenue for Q4 2024 (Oct-Dec)? | C8: 4 | D8: =SUMIFS(Orders!$I:$I,Orders!$B:$B,">="&DATE(2024,10,1),Orders!$B:$B,"<"&DATE(2025,1,1)) -> 6459443 | E8: Currency
A9: Q4.5 | B9: Create a CALCULATED FIELD in the pivot: profit_margin = (unit_price - unit_cost) / unit_price. What is the AVERAGE profit_margin for orders shipped to Delhi? Give as a percentage. | C9: 4 | D9: 0.449 | E9: Percentage
E13: Sum of final_amount | F13: category
E14: sales_region | F14: Apparel | G14: Beauty | H14: Electronics | I14: Grocery | J14: Home | K14: Sports | L14: (blank) | M14: Grand Total
E15: East | F15: 860762.23 | G15: 1271152.8 | H15: 1214881.9 | I15: 1168089.9 | J15: 1124233.5 | K15: 945710.08 | M15: 6584830.5
E16: North | F16: 979380.97 | G16: 1556120.2 | H16: 1450710.7 | I16: 1118963.8 | J16: 867033.27 | K16: 1011820.5 | M16: 6984029.5
E17: South | F17: 962768.31 | G17: 1590646.1 | H17: 1314107.4 | I17: 1041400.8 | J17: 1140277.8 | K17: 1095843.5 | M17: 7145043.8
E18: West | F18: 868240.03 | G18: 1188460 | H18: 993053.05 | I18: 997265.82 | J18: 955407.58 | K18: 856617.89 | M18: 5859044.4
E19: (blank)
E20: Grand Total | F20: 3671151.5 | G20: 5606379.1 | H20: 4972753.1 | I20: 4325720.4 | J20: 4086952.2 | K20: 3909991.9 | M20: 26572948
E24: Sum of final_amount | F24: sales_rep_id
E25: order_month | F25: R001 | G25: R002 | H25: R003 | I25: R004 | J25: R005 | K25: R006 | L25: R007 | M25: R008 | N25: R009 | O25: R010 | P25: R011 | Q25: R012 | R25: R013 | S25: R014 | T25: R015 | U25: R016 | V25: R017 | W25: R018 | X25: R019 | Y25: R020 | Z25: R021 | AA25: R022 | AB25: R023 | AC25: R024 | AD25: R025 | AE25: R026 | AF25: R027 | AG25: R028 | AH25: R029 | AI25: R030 | AJ25: (blank) | AK25: Grand Total
E26: Apr-24 | F26: 33643.48 | G26: 46286.92 | H26: 96349.86 | I26: 23036.54 | J26: 46025.56 | K26: 170939.91 | L26: 48536.18 | M26: 12044.56 | N26: 74565.16 | O26: 41398.06 | P26: 30549.1 | Q26: 24950.8 | R26: 41420.61 | S26: 101517.17 | T26: 107626.6 | U26: 75094.84 | V26: 32212.65 | W26: 210613.93 | X26: 112510.04 | Y26: 49921.2 | Z26: 71054.8 | AA26: 93303.02 | AB26: 216421.52 | AC26: 56736.5 | AD26: 49945.92 | AE26: 131132.88 | AF26: 78106.28 | AG26: 45577.73 | AH26: 124581.45 | AI26: 36350.86 | AK26: 2282454.1
E27: Aug-24 | F27: 92676.92 | G27: 134500.5 | H27: 114656.27 | I27: 55975.34 | J27: 15060.28 | K27: 61857.9 | L27: 70196.8 | M27: 61043.44 | N27: 116575.85 | O27: 111335.79 | P27: 129473.96 | Q27: 115185.59 | R27: 70557.86 | S27: 113977.94 | T27: 114985.86 | U27: 119357.27 | V27: 88015.95 | W27: 26814.3 | X27: 20666.8 | Y27: 107718.33 | Z27: 44212.2 | AA27: 81133.64 | AB27: 50585.6 | AC27: 66015.24 | AD27: 61143.74 | AE27: 89359.82 | AF27: 18606.83 | AG27: 168231.25 | AH27: 134005.79 | AI27: 74000.9 | AK27: 2527928
E28: Dec-24 | F28: 79450.52 | G28: 47673.25 | H28: 12325.54 | I28: 59066.32 | J28: 68580.8 | K28: 121741.5 | L28: 57922.93 | M28: 172732.12 | N28: 46691.02 | O28: 70844.79 | Q28: 125492.57 | R28: 63120.66 | S28: 105996.29 | T28: 73235.58 | U28: 2821.88 | V28: 71637.3 | W28: 45259.32 | X28: 118258.66 | Y28: 24872.76 | Z28: 40227.24 | AA28: 119758.46 | AB28: 102626.04 | AC28: 104737.79 | AD28: 59696.52 | AE28: 60332.9 | AF28: 104514.17 | AG28: 51024.5 | AH28: 125575.3 | AI28: 47706.74 | AK28: 2183923.5
E29: Feb-24 | F29: 127005.17 | G29: 125187.78 | H29: 32452 | I29: 58818.56 | J29: 57914.81 | K29: 34581.99 | L29: 130276.04 | M29: 23463.3 | N29: 25935.55 | O29: 74555.64 | P29: 112894.06 | Q29: 110195.46 | R29: 139218.08 | S29: 79488 | T29: 89654.68 | U29: 90583.24 | V29: 27297.84 | W29: 121362.44 | X29: 97513.34 | Y29: 13855.82 | Z29: 104662.05 | AA29: 46819.11 | AB29: 120382.87 | AC29: 97833.74 | AD29: 43978.47 | AE29: 18592.26 | AF29: 80384.53 | AG29: 63178.48 | AH29: 142134.07 | AI29: 17274.29 | AK29: 2307493.7
E30: Jan-24 | F30: 43650.56 | G30: 51707.32 | H30: 54307 | I30: 57892.11 | J30: 70665.51 | K30: 84968.56 | L30: 92029.91 | M30: 61557.02 | N30: 125547.54 | O30: 43078.21 | P30: 88791.72 | Q30: 70680.03 | R30: 51609.12 | S30: 87497.74 | T30: 118901.06 | U30: 62195.84 | V30: 73856.39 | W30: 101638.5 | X30: 30895.18 | Y30: 41744.44 | Z30: 2689.92 | AA30: 158207.84 | AB30: 54606.06 | AC30: 24937.08 | AD30: 56041.84 | AE30: 12767.82 | AF30: 77569.16 | AG30: 36574 | AH30: 45369.15 | AI30: 59170.81 | AK30: 1941147.4
E31: Jul-24 | F31: 28761.2 | G31: 62949.74 | H31: 185921.75 | I31: 7823.48 | J31: 20649.35 | K31: 38479.32 | L31: 11528.24 | M31: 75853.47 | N31: 99012.62 | O31: 96008.48 | P31: 31373.22 | Q31: 75017.78 | R31: 32733.74 | S31: 74760.15 | T31: 51083.42 | U31: 70547.11 | V31: 4516.7 | W31: 41039.88 | X31: 72372.48 | Y31: 28955.71 | Z31: 72167.3 | AA31: 210918.24 | AB31: 89062.99 | AC31: 58773.84 | AD31: 140235.22 | AE31: 13927.63 | AF31: 32250.52 | AG31: 88182.8 | AH31: 60836.13 | AI31: 89271.18 | AK31: 1965013.7
E32: Jun-24 | F32: 82789.95 | G32: 82753.37 | H32: 37966.09 | I32: 42388.12 | J32: 113205.32 | K32: 191251.6 | L32: 58895.11 | M32: 82481.44 | N32: 69794.65 | O32: 29458.16 | P32: 45625.44 | Q32: 59218.28 | R32: 33836.58 | S32: 15951.6 | T32: 12840.4 | U32: 55791.51 | V32: 73782.34 | W32: 117809.47 | X32: 107491.78 | Y32: 90724.13 | Z32: 65924.82 | AA32: 61415.64 | AB32: 102315.15 | AC32: 53450.71 | AD32: 66753.66 | AE32: 19115.52 | AF32: 49268.73 | AG32: 47140.72 | AH32: 29011.88 | AI32: 67486.9 | AK32: 1965939.1
E33: Mar-24 | F33: 58208.49 | G33: 53533 | H33: 107489.23 | I33: 14394.38 | J33: 85853.43 | K33: 145435.13 | L33: 105489.83 | M33: 164615.05 | N33: 19130.39 | P33: 77891.76 | Q33: 20450.24 | R33: 80024.44 | S33: 85611.84 | T33: 67837.49 | U33: 153834.45 | V33: 120293.66 | W33: 51595.62 | X33: 68954.54 | Y33: 215416.3 | Z33: 100685.62 | AA33: 51327.36 | AB33: 82920.6 | AC33: 63984.05 | AD33: 130752.95 | AE33: 66759.36 | AF33: 36563.8 | AG33: 65497.58 | AH33: 63730.97 | AI33: 122041.06 | AK33: 2480322.6
E34: May-24 | F34: 44809.66 | G34: 89794.86 | H34: 139257.72 | I34: 140739.8 | J34: 67702.82 | K34: 78322.48 | L34: 41157.84 | M34: 67200.57 | N34: 100231.54 | O34: 83732.94 | P34: 10392.16 | Q34: 37183.63 | R34: 80787.31 | S34: 154170.2 | T34: 146185.96 | U34: 67937.96 | V34: 113791.15 | W34: 173129.47 | X34: 58746.86 | Y34: 182980.03 | Z34: 56143.78 | AA34: 8802.79 | AB34: 40444.23 | AC34: 125217.67 | AD34: 59507.42 | AE34: 30080.4 | AF34: 85103.46 | AG34: 68897.65 | AH34: 180359.49 | AI34: 47579.17 | AK34: 2580391
E35: Nov-24 | F35: 72215.41 | G35: 158277.82 | H35: 106760.75 | I35: 38491.18 | J35: 55570.99 | K35: 81500.24 | L35: 130208.9 | M35: 64537.26 | N35: 30954.96 | O35: 119201.57 | P35: 64240.8 | Q35: 69152.06 | R35: 108112.07 | S35: 50971.92 | T35: 97394.65 | U35: 26689.96 | V35: 23417.13 | W35: 84868.64 | X35: 96634.5 | Y35: 68985.01 | Z35: 53126.1 | AA35: 76504.66 | AB35: 59984.34 | AC35: 68084.65 | AD35: 103237.54 | AE35: 28769.67 | AF35: 110369.59 | AG35: 64459.77 | AH35: 65290.45 | AI35: 119624.49 | AK35: 2297637.1
E36: Oct-24 | F36: 37753.9 | G36: 35751.81 | H36: 29309.98 | I36: 43456.18 | J36: 99252.77 | K36: 52942.27 | L36: 57313.75 | M36: 26620.46 | N36: 107648.92 | O36: 64630.99 | P36: 55503.48 | Q36: 89150.85 | R36: 46714.58 | S36: 80097.18 | T36: 119179.18 | U36: 55604.09 | V36: 75670.28 | W36: 109087.31 | X36: 152548.56 | Y36: 23378.26 | Z36: 42203.75 | AA36: 73388.56 | AB36: 13975.5 | AC36: 82877.57 | AD36: 8289.03 | AE36: 79217.4 | AF36: 110709.75 | AG36: 137494.43 | AH36: 27441.88 | AI36: 40669.76 | AK36: 1977882.4
E37: Sep-24 | F37: 88884.34 | G37: 91647.29 | H37: 69896.72 | I37: 46944.28 | J37: 81963.69 | K37: 76627.83 | L37: 52194.15 | M37: 49404.64 | N37: 98466.52 | O37: 146100.57 | P37: 88472.06 | Q37: 104717.03 | R37: 63389.33 | S37: 45673.51 | T37: 92815.3 | U37: 34105.56 | V37: 75893.02 | W37: 29070.76 | X37: 34590.78 | Y37: 57555.72 | Z37: 108409.59 | AA37: 87991.22 | AB37: 50462.58 | AC37: 16909.74 | AD37: 121716.58 | AE37: 26249.42 | AF37: 133645.8 | AG37: 44209.14 | AH37: 18360.24 | AI37: 26448.21 | AK37: 2062815.6
E38: (blank)
E39: Grand Total | F39: 789849.6 | G39: 980063.66 | H39: 986692.91 | I39: 589026.29 | J39: 782445.33 | K39: 1138648.7 | L39: 855749.68 | M39: 861553.33 | N39: 914554.72 | O39: 880345.2 | P39: 735207.76 | Q39: 901394.32 | R39: 811524.38 | S39: 995713.54 | T39: 1091740.2 | U39: 814563.71 | V39: 780384.41 | W39: 1112289.6 | X39: 971183.52 | Y39: 906107.71 | Z39: 761507.17 | AA39: 1069570.5 | AB39: 983787.48 | AC39: 819558.58 | AD39: 901298.89 | AE39: 576305.08 | AF39: 917092.62 | AG39: 880468.05 | AH39: 1016696.8 | AI39: 747624.37 | AK39: 26572948
E43: Sum of final_amount | F43: category
E44: sales_region | F44: Apparel | G44: Beauty | H44: Electronics | I44: Grocery | J44: Home | K44: Sports | L44: (blank) | M44: Grand Total
E45: East | F45: 0.13071897 | G45: 0.1930426 | H45: 0.18449707 | I45: 0.17739104 | J45: 0.17073083 | K45: 0.1436195 | L45: 0 | M45: 1
E46: North | F46: 0.1402315 | G46: 0.22281123 | H46: 0.2077183 | I46: 0.16021751 | J46: 0.12414513 | K46: 0.14487632 | L46: 0 | M46: 1
E47: South | F47: 0.13474631 | G47: 0.22262229 | H47: 0.18391873 | I47: 0.14575149 | J47: 0.15959004 | K47: 0.15337113 | L47: 0 | M47: 1
E48: West | F48: 0.14818799 | G48: 0.20284196 | H48: 0.16949062 | I48: 0.17020964 | J48: 0.16306543 | K48: 0.14620437 | L48: 0 | M48: 1
E49: (blank) | F49: #DIV/0! | G49: #DIV/0! | H49: #DIV/0! | I49: #DIV/0! | J49: #DIV/0! | K49: #DIV/0! | L49: #DIV/0! | M49: #DIV/0!
E50: Grand Total | F50: 0.13815372 | G50: 0.21098069 | H50: 0.18713592 | I50: 0.16278662 | J50: 0.15380123 | K50: 0.14714182 | L50: 0 | M50: 1
...

Sheet Q5_Advanced
A1: Q5 - ADVANCED (10 marks total)
A2: RANK · Running Totals · TEXTJOIN · LARGE + INDEX/MATCH · Multi-condition top-N
A3: Q# | B3: Question | C3: Marks | D3: Your Answer | E3: Format
A4: Q5.1 | B4: Rank all sales reps by total revenue (highest = rank 1). Who (name) is at RANK #7? | C4: 2 | D4: {=_xlfn.LET(_xlpm.ids,Sales_Reps!$A$2:$A$31,_xlpm.names,Sales_Reps!$B$2:$B$31,_xlpm.rev,SUMIF(Orders!$E$2:$E$2001,_xlpm.ids,Orders!$I$2:$I$2001),INDEX(_xlpm.names,MATCH(LARGE(_xlpm.rev,7),_xlpm.rev,0)))} -> Amit Singh | E4: Text
A5: Q5.2 | B5: What is the CUMULATIVE revenue from Jan 2024 through the end of Aug 2024? (Sum of final_amount where order_date <= 31-Aug-2024.) | C5: 2 | D5: =SUMIFS(Orders!$I$2:$I$2001,Orders!$B$2:$B$2001,"<="&DATE(2024,8,31)) -> 18050690 | E5: Currency
A6: Q5.3 | B6: Among orders where the sales rep is in the WEST region: which product (by name) has the 2nd highest total revenue? | C6: 3 | D6: {=_xlfn.LET(_xlpm.products,Products!$A$2:$A$61,_xlpm.names,Products!$B$2:$B$61,_xlpm.westreps,_xlfn._xlws.FILTER(Sales_Reps!$A$2:$A$31,Sales_Reps!$C$2:$C$31="West"),_xlpm.revenue,_xlfn.MAP(_xlpm.products,_xlfn.LAMBDA(_xlpm.p,SUM(SUMIFS(Orders!$I$2:$I$2001,Orders!$D$2:$D$2001,_xlpm.p,Orders!$E$2:$E$2001,_xlpm.westreps)))),INDEX(_xlpm.names,MATCH(LARGE(_xlpm.revenue,2),_xlpm.revenue,0)))} -> Smart Watch | E6: Text
A7: Q5.4 | B7: Concatenate the names of the top 5 reps by revenue into a single cell, separated by " | " (space-pipe-space). | C7: 2 | D7: {=_xlfn.LET(_xlpm.ids,Sales_Reps!$A$2:$A$31,_xlpm.names,Sales_Reps!$B$2:$B$31,_xlpm.rev,SUMIF(Orders!$E$2:$E$2001,_xlpm.ids,Orders!$I$2:$I$2001),_xlfn.TEXTJOIN(" | ",TRUE,INDEX(_xlfn.SORTBY(_xlpm.names,_xlpm.rev,-1),_xlfn.SEQUENCE(5))))} -> Neha Desai | Shalini Patel | Deepak Shah | Nisha Menon | Arun Iyer | E7: Text
A8: Q5.5 | B8: What is the HIGHEST single order value (final_amount) where ship_city = "Bengaluru" AND the product's category = "Grocery"? | C8: 1 | D8: {=_xlfn.LET(_xlpm.grocery,_xlfn._xlws.FILTER(Products!$A$2:$A$61,Products!$C$2:$C$61="Grocery"),MAX(_xlfn._xlws.FILTER(Orders!$I$2:$I$2001,(Orders!$K$2:$K$2001="Bengaluru")*ISNUMBER(_xlfn.XMATCH(Orders!$D$2:$D$2001,_xlpm.grocery)))))} -> 22134 | E8: Currency
